Issue while building the feature

Traceback (most recent call last):
  File "src/genie/cli/commands/learn.py", line 365, in genie.cli.commands.learn.LearnCommand._retrieve_ops
  File "/home/devasc/Concepcion_FinalCaseStudy/pyats/lib/python3.8/site-packages/genie/libs/ops/eigrp/iosxe/eigrp.py", line 134, in learn
    self.make(final_call=True)
  File "/home/devasc/Concepcion_FinalCaseStudy/pyats/lib/python3.8/site-packages/genie/ops/base/base.py", line 101, in make
    self.maker.make(*args, **kwargs)
  File "src/genie/ops/base/maker.py", line 312, in genie.ops.base.maker.Maker.make
  File "src/genie/ops/base/maker.py", line 418, in genie.ops.base.maker.Maker._call_parser
  File "src/genie/metaparser/_metaparser.py", line 279, in genie.metaparser._metaparser.MetaParser.parse
  File "/home/devasc/Concepcion_FinalCaseStudy/pyats/lib/python3.8/site-packages/genie/libs/parser/iosxe/show_eigrp.py", line 673, in cli
    return super().cli(output=show_output, vrf=vrf)
  File "/home/devasc/Concepcion_FinalCaseStudy/pyats/lib/python3.8/site-packages/genie/libs/parser/iosxe/show_eigrp.py", line 536, in cli
    ip_dict = eigrp_instance_dict\
UnboundLocalError: local variable 'eigrp_instance_dict' referenced before assignment
